Workbook

Sheet Presentation brief
A2: Halloween assortment — team presentation brief
A4: Decision status | B4: =IF(B8>0,"Pending: "&B8&" products need a team decision",IF(AND('Team summary'!H25="Within limits",'Team summary'!I25="OK",'Team summary'!B45="OK",D8=0),"Ready for presentation review","Review constraints or missing rationale")) -> Review constraints or missing rationale
A6: Store products | B6: Count | C6: Store facings | D6: Target 16 | E6: Online products | F6: Maximum 4
A7: Chosen | B7: ='Team summary'!B25 -> 13 | C7: Used | D7: ='Team summary'!C25 -> 16 | E7: Chosen | F7: ='Team summary'!D25 -> 4
A8: Pending decisions | B8: =26-(COUNTIFS('Product decisions'!$J$7:$J$32,"In-Store")+COUNTIFS('Product decisions'!$J$7:$J$32,"Online-Only")+COUNTIFS('Product decisions'!$J$7:$J$32,"Removed")) -> 0 | C8: Decided, no rationale | D8: =COUNTIFS('Product decisions'!J7:J32,"In-Store",'Product decisions'!M7:M32,"")+COUNTIFS('Product decisions'!J7:J32,"Online-Only",'Product decisions'!M7:M32,"")+COUNTIFS('Product decisions'!J7:J32,"Removed",'Product decisions'!M7:M32,"") -> 26 | E8: Categories in-store | F8: =IF('Team summary'!E25>0,1,0)+IF('Team summary'!F25>0,1,0)+IF('Team summary'!G25>0,1,0) -> 3
A10: Compare the AI approaches — these are options, not your team’s selections.
A11: Approach | B11: Purpose | C11: Product spend | D11: Base profit* | E11: Downside profit* | F11: Store / online items
A12: Balanced | B12: Balance profit, variety and cash exposure. | C12: ='Team summary'!C7 -> 15130500 | D12: ='Team summary'!F7 -> 14367432 | E12: ='Team summary'!F8 -> 6209304 | F12: ='Team summary'!B22&" / "&'Team summary'!D22 -> 13 / 4
A13: Maximum profit | B13: Maximize modeled profit; no buying budget. | C13: ='Team summary'!C10 -> 27609500 | D13: ='Team summary'!F10 -> 22227912 | E13: ='Team summary'!F11 -> 9060568.1 | F13: ='Team summary'!B23&" / "&'Team summary'!D23 -> 11 / 4
A14: Lower investment | B14: Minimize spend; keep ≥90% of Balanced base profit. | C14: ='Team summary'!C13 -> 12124500 | D14: ='Team summary'!F13 -> 13118779 | E14: ='Team summary'!F14 -> 6321193.9 | F14: ='Team summary'!B24&" / "&'Team summary'!D24 -> 12 / 3
A15: Team choice | B15: Your selections; still pending until all products are decided. | C15: =IF(B8>0,"Pending",'Team summary'!C16) -> 13804500 | D15: =IF(B8>0,"Pending",'Team summary'!F16) -> 13899147 | E15: =IF(B8>0,"Pending",'Team summary'!F17) -> 6233204.8 | F15: ='Team summary'!B25&" / "&'Team summary'!D25 -> 13 / 4
A17: *Modeled profit = sales minus the cost of the entire order, including unsold units. It excludes operating expenses. The downside is a stress scenario, not a forecast.
A19: How the team uses this workbook
A20: 1. Review Product evidence; compare the three AI options on Product decisions.
A21: 2. Change Team choice from Undecided to In-Store, Online-Only or Removed. Add your team’s reason in Team rationale.
A22: 3. Use the chosen rows, reasons and completed totals for slides. Address tradeoffs, then add the required bonus-product pitch and honest AI reflection.
A24: Where the information came from | B24: What to say in the presentation
A25: Supplied event documents | B25: Historical performance, unit costs, prices, facings, ratings and review counts; supplier minimum order quantities and claims. Rules: exactly 16 store facings, up to four online-only items, and all three categories.
A26: Your priorities and edits | B26: Use store space efficiently; consider margin dollars, return on product spending and mandatory buys; compare current and new items; pair ratings with review counts; use channel shares. You set all 26 choices to Undecided for team review.
A27: AI calculations | B27: Channel unit shares, margin and return calculations, clearance exposure, and complete alternative assortments. Calculated results are derived from supplied inputs; they are not additional observed sales.
A28: AI judgment and assumptions | B28: Balanced recommendation, product tradeoffs and demand stress cases. New-item demand, channel recapture and clearance outcomes are assumptions in Assumptions. The optimizer does not measure traffic-building or cannibalization.
A29: Team decisions — still pending | B29: The Team choice and Team rationale fields belong to your team. AI suggestions remain separate. Undecided is excluded from partial selected totals and prevents a final presentation total.
A31: Source / limitation | B31: Reference
A32: Source workbook | B32: Halloween_Line Review Case Study_Data - Copy.xlsx — Student Data rows 6–21 and 27–36; Glossary. Original supplied file remains unchanged.
A33: Event instructions | B33: Hometown AI Innovation Challenge Case Study_Instructions - Students.pdf — pages 1–3. VP audience; eight minutes, maximum 10 slides; bonus item and AI reflection required.
A34: Interpretation limits | B34: Channel shares are units, not revenue. Prior online-only availability explains 100% online share. New items have no supplied sales or reviews. All current items recovered product cost in last season’s data.
A35: Detailed support | B35: The original analysis and source tabs are retained but hidden to keep the working view compact. Unhide them if you need to trace a figure. Edit demand and purchase controls on Assumptions.

Sheet Product decisions
A2: Team decisions — compare, choose, explain
A4: AI options: Balanced, Maximum profit, Lower investment. Your decision: Team choice. Keep Undecided until discussed; write your reason in Team rationale.
A6: Product | B6: Current / new | C6: Balanced | D6: Required facings | E6: Why keep, move, remove or pass | F6: Average stars | G6: Review count | H6: Maximum profit | I6: Lower investment | J6: Team choice | K6: Category | L6: Optimizer tradeoff | M6: Team rationale | O6: Team choice
A7: 12 ft Giant Skeleton | B7: Current | C7: In-Store | D7: =VLOOKUP(A7,'Source data'!$A$7:$D$32,4,FALSE) -> 3 | E7: ="KEEP: proven centerpiece. $6.62m historical gross profit; 95% full-price sell-through. Three facings earn strong profit. 4.5 stars from 1,200 reviews. Traffic-building value is not captured in the optimizer."&" Historical unit mix: "&TEXT(VLOOKUP(A7,'Channel evidence'!$A$7:$E$32,4,FALSE),"0%")&" store / "&TEXT(VLOOKUP(A7,'Channel evidence'!$A$7:$E$32,5,FALSE),"0%")&" online." -> KEEP: proven centerpiece. $6.62m historical gross profit; 95% full-price sell-through. Three facings earn strong profit. 4.5 stars from 1,200 reviews. Traffic-building value is not captured in the optimizer. Historical unit mix: 45% store / 55% online. | F7: 4.5 | G7: 1200 | H7: Online-Only | I7: Online-Only | J7: In-Store | K7: Giants & Animatronics | L7: Maximum profit: Online-Only. Lower investment: Online-Only. Both optimizers ignore unmeasured store traffic benefits.
A8: 9 ft Animated Pirate Ship | B8: Current | C8: Online-Only | D8: =VLOOKUP(A8,'Source data'!$A$7:$D$32,4,FALSE) -> 2 | E8: ="MOVE ONLINE: 70% of units sold online; frees two facings. Only 60% full-price sell-through. Reduce future buying exposure if supplier terms allow; the model keeps last season’s quantity for comparability."&" Historical unit mix: "&TEXT(VLOOKUP(A8,'Channel evidence'!$A$7:$E$32,4,FALSE),"0%")&" store / "&TEXT(VLOOKUP(A8,'Channel evidence'!$A$7:$E$32,5,FALSE),"0%")&" online." -> MOVE ONLINE: 70% of units sold online; frees two facings. Only 60% full-price sell-through. Reduce future buying exposure if supplier terms allow; the model keeps last season’s quantity for comparability. Historical unit mix: 30% store / 70% online. | F8: 4.3 | G8: 95 | H8: Online-Only | I8: Removed | J8: Online-Only | K8: Giants & Animatronics | L8: Lower investment: Removed.
A9: 7 ft Animated Reaper | B9: Current | C9: In-Store | D9: =VLOOKUP(A9,'Source data'!$A$7:$D$32,4,FALSE) -> 1 | E9: ="KEEP: $1.81m historical gross profit from one facing; 85% full-price sell-through. 4.6 stars from 265 reviews. Strong use of limited store space."&" Historical unit mix: "&TEXT(VLOOKUP(A9,'Channel evidence'!$A$7:$E$32,4,FALSE),"0%")&" store / "&TEXT(VLOOKUP(A9,'Channel evidence'!$A$7:$E$32,5,FALSE),"0%")&" online." -> KEEP: $1.81m historical gross profit from one facing; 85% full-price sell-through. 4.6 stars from 265 reviews. Strong use of limited store space. Historical unit mix: 50% store / 50% online. | F9: 4.6 | G9: 265 | H9: In-Store | I9: In-Store | J9: In-Store | K9: Giants & Animatronics | L9: Same placement in all three options.
A10: 5.5 ft LED Skeleton Pony | B10: Current | C10: In-Store | D10: =VLOOKUP(A10,'Source data'!$A$7:$D$32,4,FALSE) -> 1 | E10: ="KEEP: $129 middle price point, 63.8% realized margin and $1.04m historical gross profit. 4.1 stars from 100 reviews warrant investigating quality feedback."&" Historical unit mix: "&TEXT(VLOOKUP(A10,'Channel evidence'!$A$7:$E$32,4,FALSE),"0%")&" store / "&TEXT(VLOOKUP(A10,'Channel evidence'!$A$7:$E$32,5,FALSE),"0%")&" online." -> KEEP: $129 middle price point, 63.8% realized margin and $1.04m historical gross profit. 4.1 stars from 100 reviews warrant investigating quality feedback. Historical unit mix: 55% store / 45% online. | F10: 4.1 | G10: 100 | H10: In-Store | I10: In-Store | J10: In-Store | K10: Giants & Animatronics | L10: Same placement in all three options.
A11: 10.5 ft Licensed Character Inflatable | B11: Current | C11: Removed | D11: =VLOOKUP(A11,'Source data'!$A$7:$D$32,4,FALSE) -> 2 | E11: ="REMOVE: two facings generated only $46,600 gross profit, a 4.2% margin. Cost $132 against $149 retail leaves little clearance cushion. 4.8 stars from 220 reviews do not overcome weak economics."&" Historical unit mix: "&TEXT(VLOOKUP(A11,'Channel evidence'!$A$7:$E$32,4,FALSE),"0%")&" store / "&TEXT(VLOOKUP(A11,'Channel evidence'!$A$7:$E$32,5,FALSE),"0%")&" online." -> REMOVE: two facings generated only $46,600 gross profit, a 4.2% margin. Cost $132 against $149 retail leaves little clearance cushion. 4.8 stars from 220 reviews do not overcome weak economics. Historical unit mix: 40% store / 60% online. | F11: 4.8 | G11: 220 | H11: Removed | I11: Removed | J11: Removed | K11: Inflatables | L11: Same placement in all three options.
A12: 9.5 ft Licensed Sandworm Inflatable | B12: Current | C12: In-Store | D12: =VLOOKUP(A12,'Source data'!$A$7:$D$32,4,FALSE) -> 1 | E12: ="KEEP: licensed variety in one facing, 80% full-price sell-through and $410,500 gross profit. 4.7 stars from 205 reviews. A deliberate variety choice; 65% online unit share makes channel placement debatable."&" Historical unit mix: "&TEXT(VLOOKUP(A12,'Channel evidence'!$A$7:$E$32,4,FALSE),"0%")&" store / "&TEXT(VLOOKUP(A12,'Channel evidence'!$A$7:$E$32,5,FALSE),"0%")&" online." -> KEEP: licensed variety in one facing, 80% full-price sell-through and $410,500 gross profit. 4.7 stars from 205 reviews. A deliberate variety choice; 65% online unit share makes channel placement debatable. Historical unit mix: 35% store / 65% online. | F12: 4.7 | G12: 205 | H12: Removed | I12: Removed | J12: In-Store | K12: Inflatables | L12: Maximum profit: Removed. Lower investment: Removed.
A13: 12 ft Reaper Inflatable | B13: Current | C13: Removed | D13: =VLOOKUP(A13,'Source data'!$A$7:$D$32,4,FALSE) -> 1 | E13: ="REMOVE: only $13,500 gross profit, a 2.5% margin, with half the purchase on clearance. 4.8 stars from 75 reviews suggest satisfaction but do not establish adequate full-price demand."&" Historical unit mix: "&TEXT(VLOOKUP(A13,'Channel evidence'!$A$7:$E$32,4,FALSE),"0%")&" store / "&TEXT(VLOOKUP(A13,'Channel evidence'!$A$7:$E$32,5,FALSE),"0%")&" online." -> REMOVE: only $13,500 gross profit, a 2.5% margin, with half the purchase on clearance. 4.8 stars from 75 reviews suggest satisfaction but do not establish adequate full-price demand. Historical unit mix: 45% store / 55% online. | F13: 4.8 | G13: 75 | H13: Removed | I13: Removed | J13: Removed | K13: Inflatables | L13: Same placement in all three options.
A14: 6 ft Scarecrow Inflatable | B14: Current | C14: In-Store | D14: =VLOOKUP(A14,'Source data'!$A$7:$D$32,4,FALSE) -> 1 | E14: ="KEEP: accessible $59 inflatable, 85% full-price sell-through, 65% store unit share. 4.6 stars from 60 reviews. Preserves an affordable inflatable price point."&" Historical unit mix: "&TEXT(VLOOKUP(A14,'Channel evidence'!$A$7:$E$32,4,FALSE),"0%")&" store / "&TEXT(VLOOKUP(A14,'Channel evidence'!$A$7:$E$32,5,FALSE),"0%")&" online." -> KEEP: accessible $59 inflatable, 85% full-price sell-through, 65% store unit share. 4.6 stars from 60 reviews. Preserves an affordable inflatable price point. Historical unit mix: 65% store / 35% online. | F14: 4.6 | G14: 60 | H14: Removed | I14: Removed | J14: In-Store | K14: Inflatables | L14: Maximum profit: Removed. Lower investment: Removed.
A15: 24 in Metal Tombstone | B15: Current | C15: In-Store | D15: =VLOOKUP(A15,'Source data'!$A$7:$D$32,4,FALSE) -> 1 | E15: ="KEEP: $24.98 entry price and 81.1% realized margin. $546,960 gross profit. Five-star average has only six reviews; do not treat it as definitive evidence of superior quality."&" Historical unit mix: "&TEXT(VLOOKUP(A15,'Channel evidence'!$A$7:$E$32,4,FALSE),"0%")&" store / "&TEXT(VLOOKUP(A15,'Channel evidence'!$A$7:$E$32,5,FALSE),"0%")&" online." -> KEEP: $24.98 entry price and 81.1% realized margin. $546,960 gross profit. Five-star average has only six reviews; do not treat it as definitive evidence of superior quality. Historical unit mix: 70% store / 30% online. | F15: 5 | G15: 6 | H15: In-Store | I15: In-Store | J15: In-Store | K15: Decor & Accessories | L15: Same placement in all three options.
A16: 5 ft Skeleton Tombstone | B16: Current | C16: In-Store | D16: =VLOOKUP(A16,'Source data'!$A$7:$D$32,4,FALSE) -> 1 | E16: ="KEEP: $574,700 gross profit and 61.2% realized margin from one facing. 4.8 stars is based on only 10 reviews. Economics are more persuasive than the small rating sample."&" Historical unit mix: "&TEXT(VLOOKUP(A16,'Channel evidence'!$A$7:$E$32,4,FALSE),"0%")&" store / "&TEXT(VLOOKUP(A16,'Channel evidence'!$A$7:$E$32,5,FALSE),"0%")&" online." -> KEEP: $574,700 gross profit and 61.2% realized margin from one facing. 4.8 stars is based on only 10 reviews. Economics are more persuasive than the small rating sample. Historical unit mix: 45% store / 55% online. | F16: 4.8 | G16: 10 | H16: In-Store | I16: In-Store | J16: In-Store | K16: Decor & Accessories | L16: Same placement in all three options.
A17: LED Fog Machine | B17: Current | C17: Removed | D17: =VLOOKUP(A17,'Source data'!$A$7:$D$32,4,FALSE) -> 1 | E17: ="REMOVE: 17,000 of 25,000 units sold on clearance. Only 32% full-price sell-through; $48,500 profit on $925,000 product cost. Cost was recovered, but little profit remained. 4.2 stars from 3,400 reviews."&" Historical unit mix: "&TEXT(VLOOKUP(A17,'Channel evidence'!$A$7:$E$32,4,FALSE),"0%")&" store / "&TEXT(VLOOKUP(A17,'Channel evidence'!$A$7:$E$32,5,FALSE),"0%")&" online." -> REMOVE: 17,000 of 25,000 units sold on clearance. Only 32% full-price sell-through; $48,500 profit on $925,000 product cost. Cost was recovered, but little profit remained. 4.2 stars from 3,400 reviews. Historical unit mix: 60% store / 40% online. | F17: 4.2 | G17: 3400 | H17: Removed | I17: Removed | J17: Removed | K17: Decor & Accessories | L17: Same placement in all three options.
A18: Pathway Light Set (6-piece) | B18: Current | C18: In-Store | D18: =VLOOKUP(A18,'Source data'!$A$7:$D$32,4,FALSE) -> 1 | E18: ="KEEP: 85% full-price sell-through, 62.9% realized margin and 70% store unit share. 4.4 stars from 480 reviews. Practical complementary purchase."&" Historical unit mix: "&TEXT(VLOOKUP(A18,'Channel evidence'!$A$7:$E$32,4,FALSE),"0%")&" store / "&TEXT(VLOOKUP(A18,'Channel evidence'!$A$7:$E$32,5,FALSE),"0%")&" online." -> KEEP: 85% full-price sell-through, 62.9% realized margin and 70% store unit share. 4.4 stars from 480 reviews. Practical complementary purchase. Historical unit mix: 70% store / 30% online. | F18: 4.4 | G18: 480 | H18: In-Store | I18: In-Store | J18: In-Store | K18: Decor & Accessories | L18: Same placement in all three options.
A19: 16 ft Inflatable Haunted Archway | B19: Current | C19: Online-Only | D19: =VLOOKUP(A19,'Source data'!$A$7:$D$32,4,FALSE) -> 3 | E19: ="KEEP ONLINE: proven online sales, 85% full-price sell-through and $534,450 gross profit. Avoids three store facings. 4.6 stars from 340 reviews."&" Historical unit mix: "&TEXT(VLOOKUP(A19,'Channel evidence'!$A$7:$E$32,4,FALSE),"0%")&" store / "&TEXT(VLOOKUP(A19,'Channel evidence'!$A$7:$E$32,5,FALSE),"0%")&" online." -> KEEP ONLINE: proven online sales, 85% full-price sell-through and $534,450 gross profit. Avoids three store facings. 4.6 stars from 340 reviews. Historical unit mix: 0% store / 100% online. | F19: 4.6 | G19: 340 | H19: Online-Only | I19: In-Store | J19: Online-Only | K19: Inflatables | L19: Lower investment: In-Store.
A20: Life-Size Animated Butler | B20: Current | C20: Online-Only | D20: =VLOOKUP(A20,'Source data'!$A$7:$D$32,4,FALSE) -> 2 | E20: ="KEEP ONLINE: 90% full-price sell-through, $916,200 gross profit and 60.4% realized margin. 4.7 stars from 210 reviews. Avoids two facings."&" Historical unit mix: "&TEXT(VLOOKUP(A20,'Channel evidence'!$A$7:$E$32,4,FALSE),"0%")&" store / "&TEXT(VLOOKUP(A20,'Channel evidence'!$A$7:$E$32,5,FALSE),"0%")&" online." -> KEEP ONLINE: 90% full-price sell-through, $916,200 gross profit and 60.4% realized margin. 4.7 stars from 210 reviews. Avoids two facings. Historical unit mix: 0% store / 100% online. | F20: 4.7 | G20: 210 | H20: Online-Only | I20: Online-Only | J20: Online-Only | K20: Giants & Animatronics | L20: Same placement in all three options.
A21: Animated Witch Cauldron | B21: Current | C21: Removed | D21: =VLOOKUP(A21,'Source data'!$A$7:$D$32,4,FALSE) -> 1 | E21: ="REMOVE FOR CAPACITY: healthy 58.9% margin, 85% full-price sell-through and 4.5 stars from 180 reviews. Its $215,375 gross profit loses the four-slot online competition. Not a loss-making product."&" Historical unit mix: "&TEXT(VLOOKUP(A21,'Channel evidence'!$A$7:$E$32,4,FALSE),"0%")&" store / "&TEXT(VLOOKUP(A21,'Channel evidence'!$A$7:$E$32,5,FALSE),"0%")&" online." -> REMOVE FOR CAPACITY: healthy 58.9% margin, 85% full-price sell-through and 4.5 stars from 180 reviews. Its $215,375 gross profit loses the four-slot online competition. Not a loss-making product. Historical unit mix: 0% store / 100% online. | F21: 4.5 | G21: 180 | H21: Removed | I21: Online-Only | J21: Online-Only | K21: Decor & Accessories | L21: Lower investment: Online-Only.
A22: Halloween Doormat Assortment | B22: Current | C22: Removed | D22: =VLOOKUP(A22,'Source data'!$A$7:$D$32,4,FALSE) -> 1 | E22: ="REMOVE: only 45% full-price sell-through and $22,370 gross profit. 4.0 stars from 55 reviews. Cheap inventory alone is not a strong customer proposition."&" Historical unit mix: "&TEXT(VLOOKUP(A22,'Channel evidence'!$A$7:$E$32,4,FALSE),"0%")&" store / "&TEXT(VLOOKUP(A22,'Channel evidence'!$A$7:$E$32,5,FALSE),"0%")&" online." -> REMOVE: only 45% full-price sell-through and $22,370 gross profit. 4.0 stars from 55 reviews. Cheap inventory alone is not a strong customer proposition. Historical unit mix: 0% store / 100% online. | F22: 4 | G22: 55 | H22: Removed | I22: Removed | J22: Removed | K22: Decor & Accessories | L22: Same placement in all three options. The up-to-four online limit removes the need for low-cost space filling.
A23: 14 ft Giant Animated Dragon | B23: New | C23: Removed | D23: =VLOOKUP(A23,'Source data'!$A$7:$D$32,4,FALSE) -> 4 | E23: PASS: mandatory 45,000 units cost $10.8m and require four facings. No supplied demand or review history. Vendor sellout claim is unverified. $224.50 half-price clearance is below $240 unit cost. Strong modeled upside, but concentrated cash and demand risk. | H23: In-Store | I23: Removed | J23: Removed | K23: Giants & Animatronics | L23: Maximum profit: In-Store.
A24: 6 ft Licensed Movie Villain | B24: New | C24: Removed | D24: =VLOOKUP(A24,'Source data'!$A$7:$D$32,4,FALSE) -> 2 | E24: PASS: 14,000-unit minimum costs $3.01m. Licensed royalty is already in cost. 34.7% full-price margin, falling to 27.4% at 80% full-price sell-through. Sitcom option requires less cash and offers better return on cost. | H24: In-Store | I24: Removed | J24: Removed | K24: Giants & Animatronics | L24: Maximum profit: In-Store.
A25: 9 ft Licensed Franchise Inflatable | B25: New | C25: Removed | D25: =VLOOKUP(A25,'Source data'!$A$7:$D$32,4,FALSE) -> 2 | E25: PASS: 12,000-unit minimum costs $1.656m. Only $21 margin at full price. Half-price clearance loses $58.50 per unit. At 80% full-price sell-through, modeled margin is just 3.6%. No ratings supplied. | H25: Removed | I25: Removed | J25: Removed | K25: Inflatables | L25: Same placement in all three options.
A26: 7 ft Licensed Sitcom Character | B26: New | C26: In-Store | D26: =VLOOKUP(A26,'Source data'!$A$7:$D$32,4,FALSE) -> 2 | E26: ADD: licensed animation with 41.2% full-price margin. 9,000-unit mandatory buy costs $1.476m versus $3.01m for Movie Villain. Still unproven and requires two facings. Source note incorrectly claims the existing Reaper has the same footprint. | H26: In-Store | I26: In-Store | J26: Removed | K26: Giants & Animatronics | L26: Same placement in all three options.
A27: 8 ft Inflatable Black Cat | B27: New | C27: In-Store | D27: =VLOOKUP(A27,'Source data'!$A$7:$D$32,4,FALSE) -> 1 | E27: ADD: classic $79 inflatable; 16,000-unit buy costs $640,000. $39 full-price unit margin. More cushion than licensed inflatable candidates, but demand remains unproven. | H27: In-Store | I27: In-Store | J27: In-Store | K27: Inflatables | L27: Same placement in all three options.
A28: 12 ft Inflatable Haunted Tree | B28: New | C28: Online-Only | D28: =VLOOKUP(A28,'Source data'!$A$7:$D$32,4,FALSE) -> 2 | E28: ADD ONLINE: 7,000-unit minimum costs $616,000. Extends oversized variety without two store facings. Vendor notes compact shipping carton. No historical online demand or ratings; model applies an 80% online demand factor. | H28: Removed | I28: In-Store | J28: In-Store | K28: Inflatables | L28: Maximum profit: Removed. Lower investment: In-Store.
A29: Fog Machine w/ Bluetooth Sound | B29: New | C29: Removed | D29: =VLOOKUP(A29,'Source data'!$A$7:$D$32,4,FALSE) -> 1 | E29: PASS: 20,000-unit minimum costs $1.04m, versus only 8,000 full-price units sold for old fog. Features do not prove a demand fix. At the old 32% full-price rate with remaining units half-price, profit would be $134,800 before other expenses. | H29: In-Store | I29: Removed | J29: Removed | K29: Decor & Accessories | L29: Maximum profit: In-Store.
A30: Animated Talking Portrait | B30: New | C30: In-Store | D30: =VLOOKUP(A30,'Source data'!$A$7:$D$32,4,FALSE) -> 1 | E30: ADD: 9,000-unit minimum costs only $63,000. 82.5% full-price margin and $39.98 price. Lower total profit than large products, but efficient capital use and in-store discovery potential. No ratings supplied. | H30: Removed | I30: In-Store | J30: In-Store | K30: Decor & Accessories | L30: Maximum profit: Removed.
A31: Solar Pathway Ghosts (4-pc) | B31: New | C31: In-Store | D31: =VLOOKUP(A31,'Source data'!$A$7:$D$32,4,FALSE) -> 1 | E31: ADD: 12,000-unit minimum costs $192,000. 64.4% full-price margin. Solar functionality adds variety; half-price clearance remains above unit cost. Check overlap with existing pathway lights. | H31: Removed | I31: In-Store | J31: In-Store | K31: Decor & Accessories | L31: Maximum profit: Removed.
A32: 24 in Light-Up Pumpkin Stack | B32: New | C32: In-Store | D32: =VLOOKUP(A32,'Source data'!$A$7:$D$32,4,FALSE) -> 1 | E32: ADD: $29.98 entry item; 22,000-unit minimum costs $198,000. 70.0% full-price margin. Half-price clearance still earns $5.99 per unit before expenses. Quantity is substantial but cash exposure is relatively low. | H32: In-Store | I32: In-Store | J32: In-Store | K32: Decor & Accessories | L32: Same placement in all three options.

Sheet Product evidence
A2: Product evidence — facts first, AI interpretation last
A4: Current items: supplied historical results. Channel shares use units sold; ratings show the average and number of reviews.
A6: Current product | B6: Actual gross profit / margin | C6: Full-price sell-through | D6: Store / online units % | E6: Stars (reviews) | F6: AI consideration
A7: ='Source data'!A7 -> 12 ft Giant Skeleton | B7: =TEXT('Source data'!O7,"$#,##0")&" / "&TEXT('Source data'!O7/'Source data'!N7,"0.0%") -> $6,621,000 / 56.8% | C7: ='Source data'!H7/'Source data'!G7 -> 0.95 | D7: =TEXT('Source data'!J7/SUM('Source data'!J7:K7),"0%")&" / "&TEXT('Source data'!K7/SUM('Source data'!J7:K7),"0%") -> 45% / 55% | E7: =TEXT('Source data'!L7,"0.0")&" ("&TEXT('Source data'!M7,"#,##0")&")" -> 4.5 (1,200) | F7: Proven hero; 3 facings. Keeping it in-store is a deliberate traffic/demo judgment despite 55% online sales.
A8: ='Source data'!A8 -> 9 ft Animated Pirate Ship | B8: =TEXT('Source data'!O8,"$#,##0")&" / "&TEXT('Source data'!O8/'Source data'!N8,"0.0%") -> $1,216,800 / 42.4% | C8: ='Source data'!H8/'Source data'!G8 -> 0.6 | D8: =TEXT('Source data'!J8/SUM('Source data'!J8:K8),"0%")&" / "&TEXT('Source data'!K8/SUM('Source data'!J8:K8),"0%") -> 30% / 70% | E8: =TEXT('Source data'!L8,"0.0")&" ("&TEXT('Source data'!M8,"#,##0")&")" -> 4.3 (95) | F8: 70% online supports moving it online; low full-price sell-through suggests purchase risk.
A9: ='Source data'!A9 -> 7 ft Animated Reaper | B9: =TEXT('Source data'!O9,"$#,##0")&" / "&TEXT('Source data'!O9/'Source data'!N9,"0.0%") -> $1,812,900 / 58.5% | C9: ='Source data'!H9/'Source data'!G9 -> 0.85 | D9: =TEXT('Source data'!J9/SUM('Source data'!J9:K9),"0%")&" / "&TEXT('Source data'!K9/SUM('Source data'!J9:K9),"0%") -> 50% / 50% | E9: =TEXT('Source data'!L9,"0.0")&" ("&TEXT('Source data'!M9,"#,##0")&")" -> 4.6 (265) | F9: Strong profit from one facing; equal store/online split.
A10: ='Source data'!A10 -> 5.5 ft LED Skeleton Pony | B10: =TEXT('Source data'!O10,"$#,##0")&" / "&TEXT('Source data'!O10/'Source data'!N10,"0.0%") -> $1,037,400 / 63.8% | C10: ='Source data'!H10/'Source data'!G10 -> 0.8 | D10: =TEXT('Source data'!J10/SUM('Source data'!J10:K10),"0%")&" / "&TEXT('Source data'!K10/SUM('Source data'!J10:K10),"0%") -> 55% / 45% | E10: =TEXT('Source data'!L10,"0.0")&" ("&TEXT('Source data'!M10,"#,##0")&")" -> 4.1 (100) | F10: Healthy margin and mid-price option; investigate the 4.1-star feedback.
A11: ='Source data'!A11 -> 10.5 ft Licensed Character Inflatable | B11: =TEXT('Source data'!O11,"$#,##0")&" / "&TEXT('Source data'!O11/'Source data'!N11,"0.0%") -> $46,600 / 4.2% | C11: ='Source data'!H11/'Source data'!G11 -> 0.85 | D11: =TEXT('Source data'!J11/SUM('Source data'!J11:K11),"0%")&" / "&TEXT('Source data'!K11/SUM('Source data'!J11:K11),"0%") -> 40% / 60% | E11: =TEXT('Source data'!L11,"0.0")&" ("&TEXT('Source data'!M11,"#,##0")&")" -> 4.8 (220) | F11: Only 4.2% realized margin across two facings; ratings do not fix the economics.
A12: ='Source data'!A12 -> 9.5 ft Licensed Sandworm Inflatable | B12: =TEXT('Source data'!O12,"$#,##0")&" / "&TEXT('Source data'!O12/'Source data'!N12,"0.0%") -> $410,500 / 33.9% | C12: ='Source data'!H12/'Source data'!G12 -> 0.8 | D12: =TEXT('Source data'!J12/SUM('Source data'!J12:K12),"0%")&" / "&TEXT('Source data'!K12/SUM('Source data'!J12:K12),"0%") -> 35% / 65% | E12: =TEXT('Source data'!L12,"0.0")&" ("&TEXT('Source data'!M12,"#,##0")&")" -> 4.7 (205) | F12: Licensed variety in one facing; 65% online challenges the store recommendation.
A13: ='Source data'!A13 -> 12 ft Reaper Inflatable | B13: =TEXT('Source data'!O13,"$#,##0")&" / "&TEXT('Source data'!O13/'Source data'!N13,"0.0%") -> $13,500 / 2.5% | C13: ='Source data'!H13/'Source data'!G13 -> 0.5 | D13: =TEXT('Source data'!J13/SUM('Source data'!J13:K13),"0%")&" / "&TEXT('Source data'!K13/SUM('Source data'!J13:K13),"0%") -> 45% / 55% | E13: =TEXT('Source data'!L13,"0.0")&" ("&TEXT('Source data'!M13,"#,##0")&")" -> 4.8 (75) | F13: Half sold on clearance; only 2.5% realized margin.
A14: ='Source data'!A14 -> 6 ft Scarecrow Inflatable | B14: =TEXT('Source data'!O14,"$#,##0")&" / "&TEXT('Source data'!O14/'Source data'!N14,"0.0%") -> $391,500 / 35.9% | C14: ='Source data'!H14/'Source data'!G14 -> 0.85 | D14: =TEXT('Source data'!J14/SUM('Source data'!J14:K14),"0%")&" / "&TEXT('Source data'!K14/SUM('Source data'!J14:K14),"0%") -> 65% / 35% | E14: =TEXT('Source data'!L14,"0.0")&" ("&TEXT('Source data'!M14,"#,##0")&")" -> 4.6 (60) | F14: Affordable inflatable; 65% store share supports store placement.
A15: ='Source data'!A15 -> 24 in Metal Tombstone | B15: =TEXT('Source data'!O15,"$#,##0")&" / "&TEXT('Source data'!O15/'Source data'!N15,"0.0%") -> $546,960 / 81.1% | C15: ='Source data'!H15/'Source data'!G15 -> 0.8 | D15: =TEXT('Source data'!J15/SUM('Source data'!J15:K15),"0%")&" / "&TEXT('Source data'!K15/SUM('Source data'!J15:K15),"0%") -> 70% / 30% | E15: =TEXT('Source data'!L15,"0.0")&" ("&TEXT('Source data'!M15,"#,##0")&")" -> 5.0 (6) | F15: High margin and 70% store share; only six reviews behind the five-star average.
A16: ='Source data'!A16 -> 5 ft Skeleton Tombstone | B16: =TEXT('Source data'!O16,"$#,##0")&" / "&TEXT('Source data'!O16/'Source data'!N16,"0.0%") -> $574,700 / 61.2% | C16: ='Source data'!H16/'Source data'!G16 -> 0.8 | D16: =TEXT('Source data'!J16/SUM('Source data'!J16:K16),"0%")&" / "&TEXT('Source data'!K16/SUM('Source data'!J16:K16),"0%") -> 45% / 55% | E16: =TEXT('Source data'!L16,"0.0")&" ("&TEXT('Source data'!M16,"#,##0")&")" -> 4.8 (10) | F16: Healthy one-facing profit; high rating is based on only 10 reviews.
A17: ='Source data'!A17 -> LED Fog Machine | B17: =TEXT('Source data'!O17,"$#,##0")&" / "&TEXT('Source data'!O17/'Source data'!N17,"0.0%") -> $48,500 / 5.0% | C17: ='Source data'!H17/'Source data'!G17 -> 0.32 | D17: =TEXT('Source data'!J17/SUM('Source data'!J17:K17),"0%")&" / "&TEXT('Source data'!K17/SUM('Source data'!J17:K17),"0%") -> 60% / 40% | E17: =TEXT('Source data'!L17,"0.0")&" ("&TEXT('Source data'!M17,"#,##0")&")" -> 4.2 (3,400) | F17: 68% sold on clearance. Recovered product cost, but left only $48,500 gross profit.
A18: ='Source data'!A18 -> Pathway Light Set (6-piece) | B18: =TEXT('Source data'!O18,"$#,##0")&" / "&TEXT('Source data'!O18/'Source data'!N18,"0.0%") -> $366,417 / 62.9% | C18: ='Source data'!H18/'Source data'!G18 -> 0.85 | D18: =TEXT('Source data'!J18/SUM('Source data'!J18:K18),"0%")&" / "&TEXT('Source data'!K18/SUM('Source data'!J18:K18),"0%") -> 70% / 30% | E18: =TEXT('Source data'!L18,"0.0")&" ("&TEXT('Source data'!M18,"#,##0")&")" -> 4.4 (480) | F18: Strong full-price demand; 70% store share supports keeping it in-store.
... A22: ='Source data'!A22 -> Halloween Doormat Assortment | B22: =TEXT('Source data'!O22,"$#,##0")&" / "&TEXT('Source data'!O22/'Source data'!N22,"0.0%") -> $22,370 / 17.2% | C22: ='Source data'!H22/'Source data'!G22 -> 0.45 | D22: =TEXT('Source data'!J22/SUM('Source data'!J22:K22),"0%")&" / "&TEXT('Source data'!K22/SUM('Source data'!J22:K22),"0%") -> 0% / 100% | E22: =TEXT('Source data'!L22,"0.0")&" ("&TEXT('Source data'!M22,"#,##0")&")" -> 4.0 (55) | F22: Weak full-price demand and low gross profit; 100% online reflects availability.
A24: New items: supplier terms, not sales forecasts. Minimum investment = mandatory quantity × unit cost. No historical channel sales or reviews supplied.
A26: New product | B26: Retail / unit cost | C26: Mandatory units | D26: Minimum investment | E26: Full-price margin | F26: AI consideration
A27: ='Source data'!A23 -> 14 ft Giant Animated Dragon | B27: =TEXT('Source data'!E23,"$0.00")&" / "&TEXT('Source data'!F23,"$0.00") -> $449.00 / $240.00 | C27: ='Source data'!G23 -> 45000 | D27: ='Source data'!G23*'Source data'!F23 -> 10800000 | E27: =1-'Source data'!F23/'Source data'!E23 -> 0.46547884 | F27: $10.8m minimum buy and four facings. High upside; unproven demand. Half-price clearance loses $15.50 per unit.
A28: ='Source data'!A24 -> 6 ft Licensed Movie Villain | B28: =TEXT('Source data'!E24,"$0.00")&" / "&TEXT('Source data'!F24,"$0.00") -> $329.00 / $215.00 | C28: ='Source data'!G24 -> 14000 | D28: ='Source data'!G24*'Source data'!F24 -> 3010000 | E28: =1-'Source data'!F24/'Source data'!E24 -> 0.34650456 | F28: $3.01m minimum buy. Lower return on cost than the sitcom option; no review history.
A29: ='Source data'!A25 -> 9 ft Licensed Franchise Inflatable | B29: =TEXT('Source data'!E25,"$0.00")&" / "&TEXT('Source data'!F25,"$0.00") -> $159.00 / $138.00 | C29: ='Source data'!G25 -> 12000 | D29: ='Source data'!G25*'Source data'!F25 -> 1656000 | E29: =1-'Source data'!F25/'Source data'!E25 -> 0.13207547 | F29: Thin full-price margin. Half-price clearance loses $58.50 per unit.
A30: ='Source data'!A26 -> 7 ft Licensed Sitcom Character | B30: =TEXT('Source data'!E26,"$0.00")&" / "&TEXT('Source data'!F26,"$0.00") -> $279.00 / $164.00 | C30: ='Source data'!G26 -> 9000 | D30: ='Source data'!G26*'Source data'!F26 -> 1476000 | E30: =1-'Source data'!F26/'Source data'!E26 -> 0.41218638 | F30: Lower cash exposure than Movie Villain; still an unproven 9,000-unit buy. Requires two facings.
A31: ='Source data'!A27 -> 8 ft Inflatable Black Cat | B31: =TEXT('Source data'!E27,"$0.00")&" / "&TEXT('Source data'!F27,"$0.00") -> $79.00 / $40.00 | C31: ='Source data'!G27 -> 16000 | D31: ='Source data'!G27*'Source data'!F27 -> 640000 | E31: =1-'Source data'!F27/'Source data'!E27 -> 0.49367089 | F31: Classic lower-price inflatable; healthier unit margin than licensed candidates. Demand unproven.
A32: ='Source data'!A28 -> 12 ft Inflatable Haunted Tree | B32: =TEXT('Source data'!E28,"$0.00")&" / "&TEXT('Source data'!F28,"$0.00") -> $179.00 / $88.00 | C32: ='Source data'!G28 -> 7000 | D32: ='Source data'!G28*'Source data'!F28 -> 616000 | E32: =1-'Source data'!F28/'Source data'!E28 -> 0.50837989 | F32: Large footprint supports online placement. Compact carton is a supplied merchant note, not verified fulfillment cost.
A33: ='Source data'!A29 -> Fog Machine w/ Bluetooth Sound | B33: =TEXT('Source data'!E29,"$0.00")&" / "&TEXT('Source data'!F29,"$0.00") -> $89.00 / $52.00 | C33: ='Source data'!G29 -> 20000 | D33: ='Source data'!G29*'Source data'!F29 -> 1040000 | E33: =1-'Source data'!F29/'Source data'!E29 -> 0.41573034 | F33: Minimum 20,000 units versus 8,000 full-price units for old fog. Features do not establish demand.
A34: ='Source data'!A30 -> Animated Talking Portrait | B34: =TEXT('Source data'!E30,"$0.00")&" / "&TEXT('Source data'!F30,"$0.00") -> $39.98 / $7.00 | C34: ='Source data'!G30 -> 9000 | D34: ='Source data'!G30*'Source data'!F30 -> 63000 | E34: =1-'Source data'!F30/'Source data'!E30 -> 0.82491246 | F34: Low cash commitment and high margin; smaller total profit. No review history.
A35: ='Source data'!A31 -> Solar Pathway Ghosts (4-pc) | B35: =TEXT('Source data'!E31,"$0.00")&" / "&TEXT('Source data'!F31,"$0.00") -> $44.98 / $16.00 | C35: ='Source data'!G31 -> 12000 | D35: ='Source data'!G31*'Source data'!F31 -> 192000 | E35: =1-'Source data'!F31/'Source data'!E31 -> 0.64428635 | F35: Healthy unit margin and modest cash commitment. Check overlap with existing pathway lights.
A36: ='Source data'!A32 -> 24 in Light-Up Pumpkin Stack | B36: =TEXT('Source data'!E32,"$0.00")&" / "&TEXT('Source data'!F32,"$0.00") -> $29.98 / $9.00 | C36: ='Source data'!G32 -> 22000 | D36: ='Source data'!G32*'Source data'!F32 -> 198000 | E36: =1-'Source data'!F32/'Source data'!E32 -> 0.69979987 | F36: Affordable entry item; half-price clearance still earns $5.99 per unit before expenses.

Sheet Assumptions
A2: Inputs and assumptions — AI modeling choices
A4: Yellow cells are editable model inputs, not supplied forecasts. Origins and limitations are on Presentation brief.
A6: Demand case | B6: Full-price demand multiplier | C6: Remaining stock sold on clearance | D6: Clearance price / retail
A7: Base | B7: 1 | C7: 1 | D7: 0.5
A8: Downside | B8: 0.7 | C8: 0.5 | D8: 0.5
A9: Upside | B9: 1.15 | C9: 1 | D9: 0.5
A12: Shared driver | B12: Value | C12: Meaning
A13: New product full-price demand / minimum | B13: 0.8 | C13: Base store demand assumption; not a vendor forecast.
A14: New online demand / store demand | B14: 0.8 | C14: Conservative online-only demand assumption for new products.
A15: Recapture of other-channel current demand | B15: 0.5 | C15: Example: store-only gets prior store units + 50% of prior online units.
A16: Lower-investment base profit floor | B16: 0.9 | C16: Solver minimizes product spend while keeping at least 90% of balanced base profit.
A20: Product | B20: Order quantity | C20: Minimum allowed | D20: Quantity check
A21: 12 ft Giant Skeleton | B21: 40000 | C21: 0 | D21: =IF(AND(ISNUMBER(B21),B21>=C21,B21>=0,MOD(B21,1)=0),"OK","Fix quantity") -> OK
A22: 9 ft Animated Pirate Ship | B22: 9000 | C22: 0 | D22: =IF(AND(ISNUMBER(B22),B22>=C22,B22>=0,MOD(B22,1)=0),"OK","Fix quantity") -> OK
A23: 7 ft Animated Reaper | B23: 12000 | C23: 0 | D23: =IF(AND(ISNUMBER(B23),B23>=C23,B23>=0,MOD(B23,1)=0),"OK","Fix quantity") -> OK
A24: 5.5 ft LED Skeleton Pony | B24: 14000 | C24: 0 | D24: =IF(AND(ISNUMBER(B24),B24>=C24,B24>=0,MOD(B24,1)=0),"OK","Fix quantity") -> OK
A25: 10.5 ft Licensed Character Inflatable | B25: 8000 | C25: 0 | D25: =IF(AND(ISNUMBER(B25),B25>=C25,B25>=0,MOD(B25,1)=0),"OK","Fix quantity") -> OK
A26: 9.5 ft Licensed Sandworm Inflatable | B26: 5000 | C26: 0 | D26: =IF(AND(ISNUMBER(B26),B26>=C26,B26>=0,MOD(B26,1)=0),"OK","Fix quantity") -> OK
A27: 12 ft Reaper Inflatable | B27: 6000 | C27: 0 | D27: =IF(AND(ISNUMBER(B27),B27>=C27,B27>=0,MOD(B27,1)=0),"OK","Fix quantity") -> OK
A28: 6 ft Scarecrow Inflatable | B28: 20000 | C28: 0 | D28: =IF(AND(ISNUMBER(B28),B28>=C28,B28>=0,MOD(B28,1)=0),"OK","Fix quantity") -> OK
A29: 24 in Metal Tombstone | B29: 30000 | C29: 0 | D29: =IF(AND(ISNUMBER(B29),B29>=C29,B29>=0,MOD(B29,1)=0),"OK","Fix quantity") -> OK
A30: 5 ft Skeleton Tombstone | B30: 7000 | C30: 0 | D30: =IF(AND(ISNUMBER(B30),B30>=C30,B30>=0,MOD(B30,1)=0),"OK","Fix quantity") -> OK
A31: LED Fog Machine | B31: 25000 | C31: 0 | D31: =IF(AND(ISNUMBER(B31),B31>=C31,B31>=0,MOD(B31,1)=0),"OK","Fix quantity") -> OK
A32: Pathway Light Set (6-piece) | B32: 18000 | C32: 0 | D32: =IF(AND(ISNUMBER(B32),B32>=C32,B32>=0,MOD(B32,1)=0),"OK","Fix quantity") -> OK
... A46: 24 in Light-Up Pumpkin Stack | B46: 22000 | C46: 22000 | D46: =IF(AND(ISNUMBER(B46),B46>=C46,B46>=0,MOD(B46,1)=0),"OK","Fix quantity") -> OK
A49: Model meaning
A50: Profit after full buy cost = sales revenue less the cost of every unit ordered.
A51: Unsold units receive zero recovery in that conservative measure; unsold inventory cost is shown separately.
A52: Gross profit on sold units is also available in Profit model; neither measure includes freight, returns, labor, royalties beyond supplied cost, or other operating expenses.
A53: Current quantity defaults to last season’s purchase, not a supplier minimum. New quantity may increase but may not fall below the mandatory minimum.
A54: Scenario placements were optimized once at the original assumptions. Formulas revalue them live; they do not rerun the discrete optimizer after edits.
A55: Demand cases use one shared row-based calculation engine. Product demand is independent; cannibalization and store traffic benefits are not estimated.

Sheet Team summary
A2: Halloween assortment: team decision brief
A4: What I Recommendation: Balanced - it has exactly 16 facings, 4 online-only items, all three categories in-store.
A6: Assortment | B6: Demand case | C6: Product purchases | D6: New-product purchases | E6: Sales revenue | F6: Profit after full buy cost | G6: Return on buy cost | H6: Unsold inventory cost | I6: Profit vs balanced | J6: Sales vs last year
A7: Balanced | B7: Base | C7: =SUMIFS('Profit model'!$L$7:$L$162,'Profit model'!$C$7:$C$162,B7,'Profit model'!$Q$7:$Q$162,1) -> 15130500 | D7: =SUMIFS('Profit model'!$U$7:$U$162,'Profit model'!$C$7:$C$162,B7,'Profit model'!$Q$7:$Q$162,1) -> 3185000 | E7: =SUMIFS('Profit model'!$K$7:$K$162,'Profit model'!$C$7:$C$162,B7,'Profit model'!$Q$7:$Q$162,1) -> 29497932 | F7: =SUMIFS('Profit model'!$N$7:$N$162,'Profit model'!$C$7:$C$162,B7,'Profit model'!$Q$7:$Q$162,1) -> 14367432 | G7: =IF(C7=0,0,F7/C7) -> 0.94956756 | H7: =SUMIFS('Profit model'!$O$7:$O$162,'Profit model'!$C$7:$C$162,B7,'Profit model'!$Q$7:$Q$162,1) -> 0 | I7: =F7-F7 -> 0 | J7: =E7-SUM('Source data'!$N$7:$N$22) -> 16260.45
A8: Balanced | B8: Downside | C8: =SUMIFS('Profit model'!$L$7:$L$162,'Profit model'!$C$7:$C$162,B8,'Profit model'!$Q$7:$Q$162,1) -> 15130500 | D8: =SUMIFS('Profit model'!$U$7:$U$162,'Profit model'!$C$7:$C$162,B8,'Profit model'!$Q$7:$Q$162,1) -> 3185000 | E8: =SUMIFS('Profit model'!$K$7:$K$162,'Profit model'!$C$7:$C$162,B8,'Profit model'!$Q$7:$Q$162,1) -> 21339804 | F8: =SUMIFS('Profit model'!$N$7:$N$162,'Profit model'!$C$7:$C$162,B8,'Profit model'!$Q$7:$Q$162,1) -> 6209304 | G8: =IF(C8=0,0,F8/C8) -> 0.41038327 | H8: =SUMIFS('Profit model'!$O$7:$O$162,'Profit model'!$C$7:$C$162,B8,'Profit model'!$Q$7:$Q$162,1) -> 3942867.2 | I8: =F8-F8 -> 0 | J8: =E8-SUM('Source data'!$N$7:$N$22) -> -8141867.5
A9: Balanced | B9: Upside | C9: =SUMIFS('Profit model'!$L$7:$L$162,'Profit model'!$C$7:$C$162,B9,'Profit model'!$Q$7:$Q$162,1) -> 15130500 | D9: =SUMIFS('Profit model'!$U$7:$U$162,'Profit model'!$C$7:$C$162,B9,'Profit model'!$Q$7:$Q$162,1) -> 3185000 | E9: =SUMIFS('Profit model'!$K$7:$K$162,'Profit model'!$C$7:$C$162,B9,'Profit model'!$Q$7:$Q$162,1) -> 31267503 | F9: =SUMIFS('Profit model'!$N$7:$N$162,'Profit model'!$C$7:$C$162,B9,'Profit model'!$Q$7:$Q$162,1) -> 16137003 | G9: =IF(C9=0,0,F9/C9) -> 1.0665215 | H9: =SUMIFS('Profit model'!$O$7:$O$162,'Profit model'!$C$7:$C$162,B9,'Profit model'!$Q$7:$Q$162,1) -> 0 | I9: =F9-F9 -> 0 | J9: =E9-SUM('Source data'!$N$7:$N$22) -> 1785831.7
A10: Maximum profit | B10: Base | C10: =SUMIFS('Profit model'!$L$7:$L$162,'Profit model'!$C$7:$C$162,B10,'Profit model'!$R$7:$R$162,1) -> 27609500 | D10: =SUMIFS('Profit model'!$U$7:$U$162,'Profit model'!$C$7:$C$162,B10,'Profit model'!$R$7:$R$162,1) -> 17164000 | E10: =SUMIFS('Profit model'!$K$7:$K$162,'Profit model'!$C$7:$C$162,B10,'Profit model'!$R$7:$R$162,1) -> 49837412 | F10: =SUMIFS('Profit model'!$N$7:$N$162,'Profit model'!$C$7:$C$162,B10,'Profit model'!$R$7:$R$162,1) -> 22227912 | G10: =IF(C10=0,0,F10/C10) -> 0.80508204 | H10: =SUMIFS('Profit model'!$O$7:$O$162,'Profit model'!$C$7:$C$162,B10,'Profit model'!$R$7:$R$162,1) -> 0 | I10: =F10-F7 -> 7860480.5 | J10: =E10-SUM('Source data'!$N$7:$N$22) -> 20355741
A11: Maximum profit | B11: Downside | C11: =SUMIFS('Profit model'!$L$7:$L$162,'Profit model'!$C$7:$C$162,B11,'Profit model'!$R$7:$R$162,1) -> 27609500 | D11: =SUMIFS('Profit model'!$U$7:$U$162,'Profit model'!$C$7:$C$162,B11,'Profit model'!$R$7:$R$162,1) -> 17164000 | E11: =SUMIFS('Profit model'!$K$7:$K$162,'Profit model'!$C$7:$C$162,B11,'Profit model'!$R$7:$R$162,1) -> 36670068 | F11: =SUMIFS('Profit model'!$N$7:$N$162,'Profit model'!$C$7:$C$162,B11,'Profit model'!$R$7:$R$162,1) -> 9060568.1 | G11: =IF(C11=0,0,F11/C11) -> 0.3281685 | H11: =SUMIFS('Profit model'!$O$7:$O$162,'Profit model'!$C$7:$C$162,B11,'Profit model'!$R$7:$R$162,1) -> 6472967.5 | I11: =F11-F8 -> 2851264 | J11: =E11-SUM('Source data'!$N$7:$N$22) -> 7188396.6
A12: Maximum profit | B12: Upside | C12: =SUMIFS('Profit model'!$L$7:$L$162,'Profit model'!$C$7:$C$162,B12,'Profit model'!$R$7:$R$162,1) -> 27609500 | D12: =SUMIFS('Profit model'!$U$7:$U$162,'Profit model'!$C$7:$C$162,B12,'Profit model'!$R$7:$R$162,1) -> 17164000 | E12: =SUMIFS('Profit model'!$K$7:$K$162,'Profit model'!$C$7:$C$162,B12,'Profit model'!$R$7:$R$162,1) -> 53014399 | F12: =SUMIFS('Profit model'!$N$7:$N$162,'Profit model'!$C$7:$C$162,B12,'Profit model'!$R$7:$R$162,1) -> 25404899 | G12: =IF(C12=0,0,F12/C12) -> 0.92015065 | H12: =SUMIFS('Profit model'!$O$7:$O$162,'Profit model'!$C$7:$C$162,B12,'Profit model'!$R$7:$R$162,1) -> 0 | I12: =F12-F9 -> 9267896.1 | J12: =E12-SUM('Source data'!$N$7:$N$22) -> 23532728
A13: Lower investment | B13: Base | C13: =SUMIFS('Profit model'!$L$7:$L$162,'Profit model'!$C$7:$C$162,B13,'Profit model'!$S$7:$S$162,1) -> 12124500 | D13: =SUMIFS('Profit model'!$U$7:$U$162,'Profit model'!$C$7:$C$162,B13,'Profit model'!$S$7:$S$162,1) -> 3185000 | E13: =SUMIFS('Profit model'!$K$7:$K$162,'Profit model'!$C$7:$C$162,B13,'Profit model'!$S$7:$S$162,1) -> 25243279 | F13: =SUMIFS('Profit model'!$N$7:$N$162,'Profit model'!$C$7:$C$162,B13,'Profit model'!$S$7:$S$162,1) -> 13118779 | G13: =IF(C13=0,0,F13/C13) -> 1.0820058 | H13: =SUMIFS('Profit model'!$O$7:$O$162,'Profit model'!$C$7:$C$162,B13,'Profit model'!$S$7:$S$162,1) -> 0 | I13: =F13-F7 -> -1248652.5 | J13: =E13-SUM('Source data'!$N$7:$N$22) -> -4238392
A14: Lower investment | B14: Downside | C14: =SUMIFS('Profit model'!$L$7:$L$162,'Profit model'!$C$7:$C$162,B14,'Profit model'!$S$7:$S$162,1) -> 12124500 | D14: =SUMIFS('Profit model'!$U$7:$U$162,'Profit model'!$C$7:$C$162,B14,'Profit model'!$S$7:$S$162,1) -> 3185000 | E14: =SUMIFS('Profit model'!$K$7:$K$162,'Profit model'!$C$7:$C$162,B14,'Profit model'!$S$7:$S$162,1) -> 18445694 | F14: =SUMIFS('Profit model'!$N$7:$N$162,'Profit model'!$C$7:$C$162,B14,'Profit model'!$S$7:$S$162,1) -> 6321193.9 | G14: =IF(C14=0,0,F14/C14) -> 0.52135708 | H14: =SUMIFS('Profit model'!$O$7:$O$162,'Profit model'!$C$7:$C$162,B14,'Profit model'!$S$7:$S$162,1) -> 2980346 | I14: =F14-F8 -> 111889.88 | J14: =E14-SUM('Source data'!$N$7:$N$22) -> -11035978
A15: Lower investment | B15: Upside | C15: =SUMIFS('Profit model'!$L$7:$L$162,'Profit model'!$C$7:$C$162,B15,'Profit model'!$S$7:$S$162,1) -> 12124500 | D15: =SUMIFS('Profit model'!$U$7:$U$162,'Profit model'!$C$7:$C$162,B15,'Profit model'!$S$7:$S$162,1) -> 3185000 | E15: =SUMIFS('Profit model'!$K$7:$K$162,'Profit model'!$C$7:$C$162,B15,'Profit model'!$S$7:$S$162,1) -> 26803728 | F15: =SUMIFS('Profit model'!$N$7:$N$162,'Profit model'!$C$7:$C$162,B15,'Profit model'!$S$7:$S$162,1) -> 14679228 | G15: =IF(C15=0,0,F15/C15) -> 1.2107079 | H15: =SUMIFS('Profit model'!$O$7:$O$162,'Profit model'!$C$7:$C$162,B15,'Profit model'!$S$7:$S$162,1) -> 0 | I15: =F15-F9 -> -1457775.4 | J15: =E15-SUM('Source data'!$N$7:$N$22) -> -2677943.6
A16: =IF(26-(COUNTIFS('Product decisions'!$J$7:$J$32,"In-Store")+COUNTIFS('Product decisions'!$J$7:$J$32,"Online-Only")+COUNTIFS('Product decisions'!$J$7:$J$32,"Removed"))>0,"Team choice (partial)","Team choice") -> Team choice | B16: Base | C16: =SUMIFS('Profit model'!$L$7:$L$162,'Profit model'!$C$7:$C$162,B16,'Profit model'!$T$7:$T$162,1) -> 13804500 | D16: =SUMIFS('Profit model'!$U$7:$U$162,'Profit model'!$C$7:$C$162,B16,'Profit model'!$T$7:$T$162,1) -> 1709000 | E16: =SUMIFS('Profit model'!$K$7:$K$162,'Profit model'!$C$7:$C$162,B16,'Profit model'!$T$7:$T$162,1) -> 27703647 | F16: =SUMIFS('Profit model'!$N$7:$N$162,'Profit model'!$C$7:$C$162,B16,'Profit model'!$T$7:$T$162,1) -> 13899147 | G16: =IF(C16=0,0,F16/C16) -> 1.0068562 | H16: =SUMIFS('Profit model'!$O$7:$O$162,'Profit model'!$C$7:$C$162,B16,'Profit model'!$T$7:$T$162,1) -> 0 | I16: =F16-F7 -> -468285 | J16: =E16-SUM('Source data'!$N$7:$N$22) -> -1778024.6
A17: =IF(26-(COUNTIFS('Product decisions'!$J$7:$J$32,"In-Store")+COUNTIFS('Product decisions'!$J$7:$J$32,"Online-Only")+COUNTIFS('Product decisions'!$J$7:$J$32,"Removed"))>0,"Team choice (partial)","Team choice") -> Team choice | B17: Downside | C17: =SUMIFS('Profit model'!$L$7:$L$162,'Profit model'!$C$7:$C$162,B17,'Profit model'!$T$7:$T$162,1) -> 13804500 | D17: =SUMIFS('Profit model'!$U$7:$U$162,'Profit model'!$C$7:$C$162,B17,'Profit model'!$T$7:$T$162,1) -> 1709000 | E17: =SUMIFS('Profit model'!$K$7:$K$162,'Profit model'!$C$7:$C$162,B17,'Profit model'!$T$7:$T$162,1) -> 20037705 | F17: =SUMIFS('Profit model'!$N$7:$N$162,'Profit model'!$C$7:$C$162,B17,'Profit model'!$T$7:$T$162,1) -> 6233204.8 | G17: =IF(C17=0,0,F17/C17) -> 0.45153427 | H17: =SUMIFS('Profit model'!$O$7:$O$162,'Profit model'!$C$7:$C$162,B17,'Profit model'!$T$7:$T$162,1) -> 3614026.2 | I17: =F17-F8 -> 23900.75 | J17: =E17-SUM('Source data'!$N$7:$N$22) -> -9443966.7
A18: =IF(26-(COUNTIFS('Product decisions'!$J$7:$J$32,"In-Store")+COUNTIFS('Product decisions'!$J$7:$J$32,"Online-Only")+COUNTIFS('Product decisions'!$J$7:$J$32,"Removed"))>0,"Team choice (partial)","Team choice") -> Team choice | B18: Upside | C18: =SUMIFS('Profit model'!$L$7:$L$162,'Profit model'!$C$7:$C$162,B18,'Profit model'!$T$7:$T$162,1) -> 13804500 | D18: =SUMIFS('Profit model'!$U$7:$U$162,'Profit model'!$C$7:$C$162,B18,'Profit model'!$T$7:$T$162,1) -> 1709000 | E18: =SUMIFS('Profit model'!$K$7:$K$162,'Profit model'!$C$7:$C$162,B18,'Profit model'!$T$7:$T$162,1) -> 29362775 | F18: =SUMIFS('Profit model'!$N$7:$N$162,'Profit model'!$C$7:$C$162,B18,'Profit model'!$T$7:$T$162,1) -> 15558275 | G18: =IF(C18=0,0,F18/C18) -> 1.1270438 | H18: =SUMIFS('Profit model'!$O$7:$O$162,'Profit model'!$C$7:$C$162,B18,'Profit model'!$T$7:$T$162,1) -> 0 | I18: =F18-F9 -> -578727.75 | J18: =E18-SUM('Source data'!$N$7:$N$22) -> -118896.01
A21: Assortment | B21: Store products | C21: Store facings | D21: Online items | E21: Giants in-store | F21: Inflatables in-store | G21: Decor in-store | H21: Placement check | I21: Quantity checks | J21: Lower-cost floor
A22: Balanced | B22: =COUNTIFS('Product decisions'!$C$7:$C$32,"In-Store") -> 13 | C22: =SUMIFS('Profit model'!$V$7:$V$162,'Profit model'!$C$7:$C$162,"Base",'Profit model'!$B$7:$B$162,"In-Store",'Profit model'!$Q$7:$Q$162,1) -> 16 | D22: =COUNTIFS('Product decisions'!$C$7:$C$32,"Online-Only") -> 4 | E22: =COUNTIFS('Product decisions'!$C$7:$C$32,"In-Store",'Source data'!$C$7:$C$32,"Giants & Animatronics") -> 4 | F22: =COUNTIFS('Product decisions'!$C$7:$C$32,"In-Store",'Source data'!$C$7:$C$32,"Inflatables") -> 3 | G22: =COUNTIFS('Product decisions'!$C$7:$C$32,"In-Store",'Source data'!$C$7:$C$32,"Decor & Accessories") -> 6 | H22: =IF(AND(C22=16,D22<=4,E22>0,F22>0,G22>0,COUNTIFS('Product decisions'!$C$7:$C$32,"In-Store")+COUNTIFS('Product decisions'!$C$7:$C$32,"Online-Only")+COUNTIFS('Product decisions'!$C$7:$C$32,"Removed")=26),"Within limits","Review choices") -> Within limits | I22: =IF(AND(COUNTIFS(Assumptions!$D$21:$D$46,"Fix quantity")=0,COUNTIFS('Profit model'!$C$7:$C$162,"Base",'Profit model'!$Q$7:$Q$162,1,'Profit model'!$D$7:$D$162,"<=0")=0),"OK","Fix quantity") -> OK
A23: Maximum profit | B23: =COUNTIFS('Product decisions'!$H$7:$H$32,"In-Store") -> 11 | C23: =SUMIFS('Profit model'!$V$7:$V$162,'Profit model'!$C$7:$C$162,"Base",'Profit model'!$B$7:$B$162,"In-Store",'Profit model'!$R$7:$R$162,1) -> 16 | D23: =COUNTIFS('Product decisions'!$H$7:$H$32,"Online-Only") -> 4 | E23: =COUNTIFS('Product decisions'!$H$7:$H$32,"In-Store",'Source data'!$C$7:$C$32,"Giants & Animatronics") -> 5 | F23: =COUNTIFS('Product decisions'!$H$7:$H$32,"In-Store",'Source data'!$C$7:$C$32,"Inflatables") -> 1 | G23: =COUNTIFS('Product decisions'!$H$7:$H$32,"In-Store",'Source data'!$C$7:$C$32,"Decor & Accessories") -> 5 | H23: =IF(AND(C23=16,D23<=4,E23>0,F23>0,G23>0,COUNTIFS('Product decisions'!$H$7:$H$32,"In-Store")+COUNTIFS('Product decisions'!$H$7:$H$32,"Online-Only")+COUNTIFS('Product decisions'!$H$7:$H$32,"Removed")=26),"Within limits","Review choices") -> Within limits | I23: =IF(AND(COUNTIFS(Assumptions!$D$21:$D$46,"Fix quantity")=0,COUNTIFS('Profit model'!$C$7:$C$162,"Base",'Profit model'!$R$7:$R$162,1,'Profit model'!$D$7:$D$162,"<=0")=0),"OK","Fix quantity") -> OK
A24: Lower investment | B24: =COUNTIFS('Product decisions'!$I$7:$I$32,"In-Store") -> 12 | C24: =SUMIFS('Profit model'!$V$7:$V$162,'Profit model'!$C$7:$C$162,"Base",'Profit model'!$B$7:$B$162,"In-Store",'Profit model'!$S$7:$S$162,1) -> 16 | D24: =COUNTIFS('Product decisions'!$I$7:$I$32,"Online-Only") -> 3 | E24: =COUNTIFS('Product decisions'!$I$7:$I$32,"In-Store",'Source data'!$C$7:$C$32,"Giants & Animatronics") -> 3 | F24: =COUNTIFS('Product decisions'!$I$7:$I$32,"In-Store",'Source data'!$C$7:$C$32,"Inflatables") -> 3 | G24: =COUNTIFS('Product decisions'!$I$7:$I$32,"In-Store",'Source data'!$C$7:$C$32,"Decor & Accessories") -> 6 | H24: =IF(AND(C24=16,D24<=4,E24>0,F24>0,G24>0,COUNTIFS('Product decisions'!$I$7:$I$32,"In-Store")+COUNTIFS('Product decisions'!$I$7:$I$32,"Online-Only")+COUNTIFS('Product decisions'!$I$7:$I$32,"Removed")=26),"Within limits","Review choices") -> Within limits | I24: =IF(AND(COUNTIFS(Assumptions!$D$21:$D$46,"Fix quantity")=0,COUNTIFS('Profit model'!$C$7:$C$162,"Base",'Profit model'!$S$7:$S$162,1,'Profit model'!$D$7:$D$162,"<=0")=0),"OK","Fix quantity") -> OK | J24: =IF(F13>=F7*Assumptions!$B$16,"Meets floor","Below floor") -> Meets floor
A25: Team choice | B25: =COUNTIFS('Product decisions'!$J$7:$J$32,"In-Store") -> 13 | C25: =SUMIFS('Profit model'!$V$7:$V$162,'Profit model'!$C$7:$C$162,"Base",'Profit model'!$B$7:$B$162,"In-Store",'Profit model'!$T$7:$T$162,1) -> 16 | D25: =COUNTIFS('Product decisions'!$J$7:$J$32,"Online-Only") -> 4 | E25: =COUNTIFS('Product decisions'!$J$7:$J$32,"In-Store",'Source data'!$C$7:$C$32,"Giants & Animatronics") -> 3 | F25: =COUNTIFS('Product decisions'!$J$7:$J$32,"In-Store",'Source data'!$C$7:$C$32,"Inflatables") -> 4 | G25: =COUNTIFS('Product decisions'!$J$7:$J$32,"In-Store",'Source data'!$C$7:$C$32,"Decor & Accessories") -> 6 | H25: =IF(26-(COUNTIFS('Product decisions'!$J$7:$J$32,"In-Store")+COUNTIFS('Product decisions'!$J$7:$J$32,"Online-Only")+COUNTIFS('Product decisions'!$J$7:$J$32,"Removed"))>0,"Pending: "&(26-(COUNTIFS('Product decisions'!$J$7:$J$32,"In-Store")+COUNTIFS('Product decisions'!$J$7:$J$32,"Online-Only")+COUNTIFS('Product decisions'!$J$7:$J$32,"Removed"))),IF(AND(C25=16,D25<=4,E25>0,F25>0,G25>0),"Within limits","Review choices")) -> Within limits | I25: =IF(AND(COUNTIFS(Assumptions!$D$21:$D$46,"Fix quantity")=0,COUNTIFS('Profit model'!$C$7:$C$162,"Base",'Profit model'!$T$7:$T$162,1,'Profit model'!$D$7:$D$162,"<=0")=0),"OK","Fix quantity") -> OK
A28: Decision guide | B28: Explanation
A29: Balanced recommendation | B29: Keeps the proven Giant Skeleton in stores, affordable inflatables and accessories, plus licensed variety. Trades some modeled profit for range and lower new-product exposure.
A30: Maximum profit | B30: Exact dynamic-programming optimum at original base assumptions: maximize profit after full buy cost with exactly 16 facings, zero to four online items and all categories in-store. No purchase budget or required hero placement.
A31: Lower investment | B31: Minimum product spend at original base assumptions, retaining at least 90% of balanced base profit, exactly 16 facings and up to four online items. The updated solution uses three online items. This is an analytical alternative, not a stated team budget.
A32: What changes live | B32: Edit Team choice on Product decisions, order quantities on Assumptions, and demand/clearance inputs. All twelve comparison rows update. Solver-generated placements remain fixed until the optimization is rerun.
A33: Why models need judgment | B33: Both optimized options move the Giant Skeleton online. Lower investment now removes doormats, keeps the Skeleton Tombstone in-store, and uses three online items. The model cannot value traffic, themes, licensed appeal, or cannibalization.
A34: Historic benchmark | B34: Last year: $29,481,672 sales and $14,775,172 gross profit on $14,706,500 product cost. All current products recovered product cost. Figures cover the supplied business dataset, not one store.
A35: Channel and demand assumptions | B35: Historical sales include both channels. Current exclusive-channel demand retains its past channel units plus 50% of the other channel, then applies historical full-price mix. New store full-price demand starts at 80% of mandatory quantity; new online at 80% of that.
A36: Downside inventory exposure | B36: Downside reduces full-price demand by 30% and clears only half of remaining stock. Unsold stock is not assumed sold; its full cost reduces the conservative profit measure. This is a scenario, not a probability forecast.
A37: Review interpretation | B37: Giant Skeleton: 4.5 average from 1,200 reviews. Metal Tombstone: 5.0 from six. Skeleton Tombstone: 4.8 from 10. Larger samples are more informative, but average ratings are not demand forecasts.
A38: New-product commitments | B38: Mandatory order quantities are not optional. Rejecting the Dragon reflects a $10.8m unproven purchase commitment, not poor modeled profit. Bluetooth fog asks for 20,000 units despite old fog selling only 8,000 at full price.
A39: Source conflict | B39: Sitcom Character requires two facings. Existing Animated Reaper requires one. Use the numeric required-facings fields, not the conflicting vendor-sheet merchant note.
... A41: Event requirements | B41: Student instructions: exactly 16 facings; zero to four online-only items; all three categories; AI reflection; no more than 10 slides and eight minutes. Four online items is a maximum, not a requirement.
A45: Demand input check | B45: =IF(AND(COUNT(Assumptions!B7:D9)=9,COUNT(Assumptions!B13:B16)=4,MIN(Assumptions!B7:D9)>=0,MAX(Assumptions!C7:C9)<=1,MAX(Assumptions!D7:D9)<1,MIN(Assumptions!B13:B16)>=0,MAX(Assumptions!B13:B16)<=1),"OK","Fix assumptions") -> OK

Sheet Assortment guide
A2: What is in each assortment?
A4: Each column is a complete alternative lineup. A product can appear in several alternatives. Definitions follow the list.
A6: Product | B6: Balanced | C6: Maximum profit | D6: Lower investment | E6: Team choice
A7: ='Product decisions'!A7 -> 12 ft Giant Skeleton | B7: =SUBSTITUTE(IF('Product decisions'!C7="In-Store","In-Store ("&VLOOKUP(A7,'Source data'!$A$7:$D$32,4,FALSE)&" facings)",'Product decisions'!C7),"(1 facings)","(1 facing)") -> In-Store (3 facings) | C7: =SUBSTITUTE(IF('Product decisions'!H7="In-Store","In-Store ("&VLOOKUP(A7,'Source data'!$A$7:$D$32,4,FALSE)&" facings)",'Product decisions'!H7),"(1 facings)","(1 facing)") -> Online-Only | D7: =SUBSTITUTE(IF('Product decisions'!I7="In-Store","In-Store ("&VLOOKUP(A7,'Source data'!$A$7:$D$32,4,FALSE)&" facings)",'Product decisions'!I7),"(1 facings)","(1 facing)") -> Online-Only | E7: =SUBSTITUTE(IF('Product decisions'!J7="In-Store","In-Store ("&VLOOKUP(A7,'Source data'!$A$7:$D$32,4,FALSE)&" facings)",'Product decisions'!J7),"(1 facings)","(1 facing)") -> In-Store (3 facings)
A8: ='Product decisions'!A8 -> 9 ft Animated Pirate Ship | B8: =SUBSTITUTE(IF('Product decisions'!C8="In-Store","In-Store ("&VLOOKUP(A8,'Source data'!$A$7:$D$32,4,FALSE)&" facings)",'Product decisions'!C8),"(1 facings)","(1 facing)") -> Online-Only | C8: =SUBSTITUTE(IF('Product decisions'!H8="In-Store","In-Store ("&VLOOKUP(A8,'Source data'!$A$7:$D$32,4,FALSE)&" facings)",'Product decisions'!H8),"(1 facings)","(1 facing)") -> Online-Only | D8: =SUBSTITUTE(IF('Product decisions'!I8="In-Store","In-Store ("&VLOOKUP(A8,'Source data'!$A$7:$D$32,4,FALSE)&" facings)",'Product decisions'!I8),"(1 facings)","(1 facing)") -> Removed | E8: =SUBSTITUTE(IF('Product decisions'!J8="In-Store","In-Store ("&VLOOKUP(A8,'Source data'!$A$7:$D$32,4,FALSE)&" facings)",'Product decisions'!J8),"(1 facings)","(1 facing)") -> Online-Only
A9: ='Product decisions'!A9 -> 7 ft Animated Reaper | B9: =SUBSTITUTE(IF('Product decisions'!C9="In-Store","In-Store ("&VLOOKUP(A9,'Source data'!$A$7:$D$32,4,FALSE)&" facings)",'Product decisions'!C9),"(1 facings)","(1 facing)") -> In-Store (1 facing) | C9: =SUBSTITUTE(IF('Product decisions'!H9="In-Store","In-Store ("&VLOOKUP(A9,'Source data'!$A$7:$D$32,4,FALSE)&" facings)",'Product decisions'!H9),"(1 facings)","(1 facing)") -> In-Store (1 facing) | D9: =SUBSTITUTE(IF('Product decisions'!I9="In-Store","In-Store ("&VLOOKUP(A9,'Source data'!$A$7:$D$32,4,FALSE)&" facings)",'Product decisions'!I9),"(1 facings)","(1 facing)") -> In-Store (1 facing) | E9: =SUBSTITUTE(IF('Product decisions'!J9="In-Store","In-Store ("&VLOOKUP(A9,'Source data'!$A$7:$D$32,4,FALSE)&" facings)",'Product decisions'!J9),"(1 facings)","(1 facing)") -> In-Store (1 facing)
